<?xml version="1.0" encoding="utf-8"?>
<!-- This URDF was automatically created by SolidWorks to URDF Exporter! Originally created by Stephen Brawner (brawner@gmail.com) 
     Commit Version: 1.6.0-4-g7f85cfe  Build Version: 1.6.7995.38578
     For more information, please see http://wiki.ros.org/sw_urdf_exporter -->
<robot
  name="microarm">
  <link
    name="base_link">
    <inertial>
      <origin
        xyz="0.0999999998495454 0.0999999997435603 0.100563741294394"
        rpy="0 0 0" />
      <mass
        value="1.83164580022402" />
      <inertia
        ixx="0.00451242425491746"
        ixy="-4.04889599747529E-07"
        ixz="-3.58891616913348E-11"
        iyy="0.00451201173117407"
        iyz="8.33413847657505E-12"
        izz="0.00749594833897759" />
    </inertial>
    <visual>
      <origin
        xyz="0 0 0"
        rpy="0 0 0" />
      <geometry>
        <mesh
          filename="package://microarm/meshes/base_link.STL" />
      </geometry>
      <material
        name="">
        <color
          rgba="0.792156862745098 0.819607843137255 0.933333333333333 1" />
      </material>
    </visual>
    <collision>
      <origin
        xyz="0 0 0"
        rpy="0 0 0" />
      <geometry>
        <mesh
          filename="package://microarm/meshes/base_link.STL" />
      </geometry>
    </collision>
  </link>
  <link
    name="Link2">
    <inertial>
      <origin
        xyz="-0.0234828470711057 -0.000267825580303332 0.0624286025870315"
        rpy="0 0 0" />
      <mass
        value="0.695485500213679" />
      <inertia
        ixx="0.00211431761193132"
        ixy="-1.54053931135612E-05"
        ixz="-6.56206336324991E-10"
        iyy="0.00286293446012588"
        iyz="3.40873220941936E-11"
        izz="0.00481019569685756" />
    </inertial>
    <visual>
      <origin
        xyz="0 0 0"
        rpy="0 0 0" />
      <geometry>
        <mesh
          filename="package://microarm/meshes/Link2.STL" />
      </geometry>
      <material
        name="">
        <color
          rgba="0.792156862745098 0.819607843137255 0.933333333333333 1" />
      </material>
    </visual>
    <collision>
      <origin
        xyz="0 0 0"
        rpy="0 0 0" />
      <geometry>
        <mesh
          filename="package://microarm/meshes/Link2.STL" />
      </geometry>
    </collision>
  </link>
  <joint
    name="J1_2"
    type="continuous">
    <origin
      xyz="0.1 0.1 0.2056"
      rpy="0 0 0" />
    <parent
      link="base_link" />
    <child
      link="Link2" />
    <axis
      xyz="0 0 1" />
    <limit
      lower="-3.1416"
      upper="3.1416"
      effort="10"
      velocity="10.472" />
  </joint>
  <link
    name="Link3">
    <inertial>
      <origin
        xyz="-0.189856429009106 -0.00390615439330114 0.0544093521407623"
        rpy="0 0 0" />
      <mass
        value="0.639692693479154" />
      <inertia
        ixx="0.0013304139813876"
        ixy="-0.000171904449677745"
        ixz="0.00274755845279573"
        iyy="0.00968219608848823"
        iyz="5.65289642098404E-05"
        izz="0.00880375321740905" />
    </inertial>
    <visual>
      <origin
        xyz="0 0 0"
        rpy="0 0 0" />
      <geometry>
        <mesh
          filename="package://microarm/meshes/Link3.STL" />
      </geometry>
      <material
        name="">
        <color
          rgba="0.792156862745098 0.819607843137255 0.933333333333333 1" />
      </material>
    </visual>
    <collision>
      <origin
        xyz="0 0 0"
        rpy="0 0 0" />
      <geometry>
        <mesh
          filename="package://microarm/meshes/Link3.STL" />
      </geometry>
    </collision>
  </link>
  <joint
    name="J2_3"
    type="continuous">
    <origin
      xyz="-0.00099979 -2.057E-05 0.11862"
      rpy="0 0 0" />
    <parent
      link="Link2" />
    <child
      link="Link3" />
    <axis
      xyz="0.02057 -0.99979 0" />
    <limit
      lower="-3.1416"
      upper="3.1416"
      effort="10"
      velocity="7.854" />
  </joint>
  <link
    name="Link4">
    <inertial>
      <origin
        xyz="0.181835532469934 0.00390913438765636 0.0329305969859985"
        rpy="0 0 0" />
      <mass
        value="0.635403008590466" />
      <inertia
        ixx="0.000499462825423093"
        ixy="-0.000177932487310486"
        ixz="-0.00131246585380149"
        iyy="0.00914411024280753"
        iyz="-2.7003004982803E-05"
        izz="0.00882569766984265" />
    </inertial>
    <visual>
      <origin
        xyz="0 0 0"
        rpy="0 0 0" />
      <geometry>
        <mesh
          filename="package://microarm/meshes/Link4.STL" />
      </geometry>
      <material
        name="">
        <color
          rgba="0.792156862745098 0.819607843137255 0.933333333333333 1" />
      </material>
    </visual>
    <collision>
      <origin
        xyz="0 0 0"
        rpy="0 0 0" />
      <geometry>
        <mesh
          filename="package://microarm/meshes/Link4.STL" />
      </geometry>
    </collision>
  </link>
  <joint
    name="J3_4"
    type="continuous">
    <origin
      xyz="-0.38 -0.0078181 0.12467"
      rpy="0 0 0" />
    <parent
      link="Link3" />
    <child
      link="Link4" />
    <axis
      xyz="0.02057 -0.99979 0" />
    <limit
      lower="-3.1416"
      upper="3.1416"
      effort="10"
      velocity="7.854" />
  </joint>
  <link
    name="Link5">
    <inertial>
      <origin
        xyz="0.022397813305375 0.000460817599175156 0.000326207354451546"
        rpy="0 0 0" />
      <mass
        value="0.289468359944892" />
      <inertia
        ixx="0.000426362303345464"
        ixy="1.77685242966266E-07"
        ixz="-4.63826034943167E-07"
        iyy="0.000417729667973413"
        iyz="-9.54287443856363E-09"
        izz="0.000330199258296266" />
    </inertial>
    <visual>
      <origin
        xyz="0 0 0"
        rpy="0 0 0" />
      <geometry>
        <mesh
          filename="package://microarm/meshes/Link5.STL" />
      </geometry>
      <material
        name="">
        <color
          rgba="0.792156862745098 0.819607843137255 0.933333333333333 1" />
      </material>
    </visual>
    <collision>
      <origin
        xyz="0 0 0"
        rpy="0 0 0" />
      <geometry>
        <mesh
          filename="package://microarm/meshes/Link5.STL" />
      </geometry>
    </collision>
  </link>
  <joint
    name="J4_5"
    type="continuous">
    <origin
      xyz="0.39526 0.0081323 0.06083"
      rpy="0 0 0" />
    <parent
      link="Link4" />
    <child
      link="Link5" />
    <axis
      xyz="0.02057 -0.99979 0" />
    <limit
      lower="-3.1416"
      upper="3.1416"
      effort="10"
      velocity="7.854" />
  </joint>
  <link
    name="Link6">
    <inertial>
      <origin
        xyz="0.056115038884047 0.0011545608181846 -0.00027548847149228"
        rpy="0 0 0" />
      <mass
        value="0.958627849549053" />
      <inertia
        ixx="0.00401143665080074"
        ixy="4.7253862654233E-05"
        ixz="-3.93877344669868E-06"
        iyy="0.00171873093473961"
        iyz="1.29144733015996E-05"
        izz="0.00326424161037811" />
    </inertial>
    <visual>
      <origin
        xyz="0 0 0"
        rpy="0 0 0" />
      <geometry>
        <mesh
          filename="package://microarm/meshes/Link6.STL" />
      </geometry>
      <material
        name="">
        <color
          rgba="0.792156862745098 0.819607843137255 0.933333333333333 1" />
      </material>
    </visual>
    <collision>
      <origin
        xyz="0 0 0"
        rpy="0 0 0" />
      <geometry>
        <mesh
          filename="package://microarm/meshes/Link6.STL" />
      </geometry>
    </collision>
  </link>
  <joint
    name="J5_6"
    type="continuous">
    <origin
      xyz="0.069987 0.0014399 0.00022212"
      rpy="0 0 0" />
    <parent
      link="Link5" />
    <child
      link="Link6" />
    <axis
      xyz="0.99978 0.02057 -0.0049082" />
    <limit
      lower="-3.1416"
      upper="3.1416"
      effort="10"
      velocity="7.854" />
  </joint>
  <link
    name="Link7">
    <inertial>
      <origin
        xyz="0.072923853261845 -0.00693173749205717 -0.000286189006702853"
        rpy="0 0 0" />
      <mass
        value="0.157213073820731" />
      <inertia
        ixx="0.000121665380990655"
        ixy="-0.000127419694012581"
        ixz="2.15850814848662E-06"
        iyy="0.000276806703521896"
        iyz="1.21706841478204E-06"
        izz="0.000349107279951105" />
    </inertial>
    <visual>
      <origin
        xyz="0 0 0"
        rpy="0 0 0" />
      <geometry>
        <mesh
          filename="package://microarm/meshes/Link7.STL" />
      </geometry>
      <material
        name="">
        <color
          rgba="0.792156862745098 0.819607843137255 0.933333333333333 1" />
      </material>
    </visual>
    <collision>
      <origin
        xyz="0 0 0"
        rpy="0 0 0" />
      <geometry>
        <mesh
          filename="package://microarm/meshes/Link7.STL" />
      </geometry>
    </collision>
  </link>
  <joint
    name="J6_7"
    type="prismatic">
    <origin
      xyz="0.083742 -0.059449 0.00010888"
      rpy="0 0 0" />
    <parent
      link="Link6" />
    <child
      link="Link7" />
    <axis
      xyz="0.02061 -0.99975 0.0084009" />
    <limit
      lower="-0.01"
      upper="0.01"
      effort="10"
      velocity="1" />
  </joint>
  <link
    name="Link8">
    <inertial>
      <origin
        xyz="0.073617906107006 0.00931469465745002 -0.000427563486490534"
        rpy="0 0 0" />
      <mass
        value="0.159934521793084" />
      <inertia
        ixx="0.000115584645862197"
        ixy="0.00012587891032655"
        ixz="9.06680737835669E-08"
        iyy="0.00029670627349042"
        iyz="-4.7677558005311E-08"
        izz="0.000361094942793925" />
    </inertial>
    <visual>
      <origin
        xyz="0 0 0"
        rpy="0 0 0" />
      <geometry>
        <mesh
          filename="package://microarm/meshes/Link8.STL" />
      </geometry>
      <material
        name="">
        <color
          rgba="0.792156862745098 0.819607843137255 0.933333333333333 1" />
      </material>
    </visual>
    <collision>
      <origin
        xyz="0 0 0"
        rpy="0 0 0" />
      <geometry>
        <mesh
          filename="package://microarm/meshes/Link8.STL" />
      </geometry>
    </collision>
  </link>
  <joint
    name="J6_8"
    type="prismatic">
    <origin
      xyz="0.081681 0.040526 -0.00073121"
      rpy="0 0 0" />
    <parent
      link="Link6" />
    <child
      link="Link8" />
    <axis
      xyz="0.02061 -0.99975 0.0084009" />
    <limit
      lower="-0.01"
      upper="0.01"
      effort="10"
      velocity="1" />
  </joint>
</robot>